2024-12-24 09:52:20,251 INFO    MainThread:161762 [internal.py:wandb_internal():86] W&B internal server running at pid: 161762, started at: 2024-12-24 09:52:20.251071
2024-12-24 09:52:20,253 INFO    WriterThread:161762 [datastore.py:open_for_write():85] open: /mnt/c/Users/jvnhe/Projects/RL-Roguelike-JAX-MARL/wandb/run-20241224_095215-rbakhqd9/run-rbakhqd9.wandb
2024-12-24 09:52:20,255 DEBUG   SenderThread:161762 [sender.py:send():380] send: header
2024-12-24 09:52:20,255 DEBUG   SenderThread:161762 [sender.py:send():380] send: run
2024-12-24 09:52:20,573 ERROR   SenderThread:161762 [internal_api.py:execute():370] 403 response executing GraphQL.
2024-12-24 09:52:20,575 ERROR   SenderThread:161762 [internal_api.py:execute():371] {"errors":[{"message":"permission denied","path":["upsertBucket"],"extensions":{"code":"PERMISSION_ERROR"}}],"data":{"upsertBucket":null}}
2024-12-24 09:52:20,575 ERROR   SenderThread:161762 [sender.py:send_run():979] It appears that you do not have permission to access the requested resource. Please reach out to the project owner to grant you access. If you have the correct permissions, verify that there are no issues with your networking setup.(Error 403: Forbidden)
Traceback (most recent call last):
  File "/mnt/c/Users/jvnhe/Projects/RL-Roguelike-JAX-MARL/lib/python3.10/site-packages/wandb/sdk/lib/retry.py", line 131, in __call__
    result = self._call_fn(*args, **kwargs)
  File "/mnt/c/Users/jvnhe/Projects/RL-Roguelike-JAX-MARL/lib/python3.10/site-packages/wandb/sdk/internal/internal_api.py", line 366, in execute
    return self.client.execute(*args, **kwargs)  # type: ignore
  File "/mnt/c/Users/jvnhe/Projects/RL-Roguelike-JAX-MARL/lib/python3.10/site-packages/wandb/vendor/gql-0.2.0/wandb_gql/client.py", line 52, in execute
    result = self._get_result(document, *args, **kwargs)
  File "/mnt/c/Users/jvnhe/Projects/RL-Roguelike-JAX-MARL/lib/python3.10/site-packages/wandb/vendor/gql-0.2.0/wandb_gql/client.py", line 60, in _get_result
    return self.transport.execute(document, *args, **kwargs)
  File "/mnt/c/Users/jvnhe/Projects/RL-Roguelike-JAX-MARL/lib/python3.10/site-packages/wandb/sdk/lib/gql_request.py", line 59, in execute
    request.raise_for_status()
  File "/mnt/c/Users/jvnhe/Projects/RL-Roguelike-JAX-MARL/lib/python3.10/site-packages/requests/models.py", line 1021, in raise_for_status
    raise HTTPError(http_error_msg, response=self)
requests.exceptions.HTTPError: 403 Client Error: Forbidden for url: https://api.wandb.ai/graphql

During handling of the above exception, another exception occurred:

Traceback (most recent call last):
  File "/mnt/c/Users/jvnhe/Projects/RL-Roguelike-JAX-MARL/lib/python3.10/site-packages/wandb/sdk/internal/sender.py", line 977, in send_run
    self._init_run(run, config_value_dict)
  File "/mnt/c/Users/jvnhe/Projects/RL-Roguelike-JAX-MARL/lib/python3.10/site-packages/wandb/sdk/internal/sender.py", line 1015, in _init_run
    server_run, inserted, server_messages = self._api.upsert_run(
  File "/mnt/c/Users/jvnhe/Projects/RL-Roguelike-JAX-MARL/lib/python3.10/site-packages/wandb/apis/normalize.py", line 73, in wrapper
    raise err
  File "/mnt/c/Users/jvnhe/Projects/RL-Roguelike-JAX-MARL/lib/python3.10/site-packages/wandb/apis/normalize.py", line 41, in wrapper
    return func(*args, **kwargs)
  File "/mnt/c/Users/jvnhe/Projects/RL-Roguelike-JAX-MARL/lib/python3.10/site-packages/wandb/sdk/internal/internal_api.py", line 2008, in upsert_run
    response = self.gql(
  File "/mnt/c/Users/jvnhe/Projects/RL-Roguelike-JAX-MARL/lib/python3.10/site-packages/wandb/sdk/internal/internal_api.py", line 338, in gql
    ret = self._retry_gql(
  File "/mnt/c/Users/jvnhe/Projects/RL-Roguelike-JAX-MARL/lib/python3.10/site-packages/wandb/sdk/lib/retry.py", line 147, in __call__
    retry_timedelta_triggered = check_retry_fn(e)
  File "/mnt/c/Users/jvnhe/Projects/RL-Roguelike-JAX-MARL/lib/python3.10/site-packages/wandb/util.py", line 965, in check_retry_fn
    return fallback_retry_fn(e)
  File "/mnt/c/Users/jvnhe/Projects/RL-Roguelike-JAX-MARL/lib/python3.10/site-packages/wandb/util.py", line 907, in no_retry_auth
    raise CommError(
wandb.errors.CommError: It appears that you do not have permission to access the requested resource. Please reach out to the project owner to grant you access. If you have the correct permissions, verify that there are no issues with your networking setup.(Error 403: Forbidden)
2024-12-24 09:52:20,659 DEBUG   HandlerThread:161762 [handler.py:handle_request():146] handle_request: shutdown
2024-12-24 09:52:20,659 INFO    HandlerThread:161762 [handler.py:finish():866] shutting down handler
2024-12-24 09:52:21,254 INFO    WriterThread:161762 [datastore.py:close():294] close: /mnt/c/Users/jvnhe/Projects/RL-Roguelike-JAX-MARL/wandb/run-20241224_095215-rbakhqd9/run-rbakhqd9.wandb
2024-12-24 09:52:21,658 INFO    SenderThread:161762 [sender.py:finish():1536] shutting down sender
